{
 "cells": [
  {
   "cell_type": "code",
   "execution_count": 11,
   "metadata": {},
   "outputs": [],
   "source": [
    "import numpy as np\n",
    "import tensorflow as tf\n",
    "from tensorflow import keras\n",
    "import tensorflow_datasets as tfds\n",
    "import matplotlib.pyplot as plt\n",
    "\n",
    "from tf_retinanet_funcs import LabelEncoder, get_backbone, RetinaNetLoss, RetinaNet, preprocess_data"
   ]
  },
  {
   "cell_type": "code",
   "execution_count": 4,
   "metadata": {},
   "outputs": [
    {
     "name": "stderr",
     "output_type": "stream",
     "text": [
      "2023-12-10 14:24:30.750473: I tensorflow/compiler/xla/stream_executor/cuda/cuda_gpu_executor.cc:995] successful NUMA node read from SysFS had negative value (-1), but there must be at least one NUMA node, so returning NUMA node zero. See more at https://github.com/torvalds/linux/blob/v6.0/Documentation/ABI/testing/sysfs-bus-pci#L344-L355\n",
      "2023-12-10 14:24:31.116756: I tensorflow/compiler/xla/stream_executor/cuda/cuda_gpu_executor.cc:995] successful NUMA node read from SysFS had negative value (-1), but there must be at least one NUMA node, so returning NUMA node zero. See more at https://github.com/torvalds/linux/blob/v6.0/Documentation/ABI/testing/sysfs-bus-pci#L344-L355\n",
      "2023-12-10 14:24:31.117333: I tensorflow/compiler/xla/stream_executor/cuda/cuda_gpu_executor.cc:995] successful NUMA node read from SysFS had negative value (-1), but there must be at least one NUMA node, so returning NUMA node zero. See more at https://github.com/torvalds/linux/blob/v6.0/Documentation/ABI/testing/sysfs-bus-pci#L344-L355\n",
      "2023-12-10 14:24:31.219078: I tensorflow/compiler/xla/stream_executor/cuda/cuda_gpu_executor.cc:995] successful NUMA node read from SysFS had negative value (-1), but there must be at least one NUMA node, so returning NUMA node zero. See more at https://github.com/torvalds/linux/blob/v6.0/Documentation/ABI/testing/sysfs-bus-pci#L344-L355\n",
      "2023-12-10 14:24:31.219653: I tensorflow/compiler/xla/stream_executor/cuda/cuda_gpu_executor.cc:995] successful NUMA node read from SysFS had negative value (-1), but there must be at least one NUMA node, so returning NUMA node zero. See more at https://github.com/torvalds/linux/blob/v6.0/Documentation/ABI/testing/sysfs-bus-pci#L344-L355\n",
      "2023-12-10 14:24:31.220119: I tensorflow/compiler/xla/stream_executor/cuda/cuda_gpu_executor.cc:995] successful NUMA node read from SysFS had negative value (-1), but there must be at least one NUMA node, so returning NUMA node zero. See more at https://github.com/torvalds/linux/blob/v6.0/Documentation/ABI/testing/sysfs-bus-pci#L344-L355\n",
      "2023-12-10 14:24:34.990359: I tensorflow/compiler/xla/stream_executor/cuda/cuda_gpu_executor.cc:995] successful NUMA node read from SysFS had negative value (-1), but there must be at least one NUMA node, so returning NUMA node zero. See more at https://github.com/torvalds/linux/blob/v6.0/Documentation/ABI/testing/sysfs-bus-pci#L344-L355\n",
      "2023-12-10 14:24:34.990779: I tensorflow/compiler/xla/stream_executor/cuda/cuda_gpu_executor.cc:995] successful NUMA node read from SysFS had negative value (-1), but there must be at least one NUMA node, so returning NUMA node zero. See more at https://github.com/torvalds/linux/blob/v6.0/Documentation/ABI/testing/sysfs-bus-pci#L344-L355\n",
      "2023-12-10 14:24:34.991138: I tensorflow/compiler/xla/stream_executor/cuda/cuda_gpu_executor.cc:995] successful NUMA node read from SysFS had negative value (-1), but there must be at least one NUMA node, so returning NUMA node zero. See more at https://github.com/torvalds/linux/blob/v6.0/Documentation/ABI/testing/sysfs-bus-pci#L344-L355\n",
      "2023-12-10 14:24:34.991512: I tensorflow/core/common_runtime/gpu/gpu_device.cc:1639] Created device /job:localhost/replica:0/task:0/device:GPU:0 with 1500 MB memory:  -> device: 0, name: NVIDIA GeForce GTX 1050, pci bus id: 0000:01:00.0, compute capability: 6.1\n"
     ]
    }
   ],
   "source": [
    "label_encoder = LabelEncoder()\n",
    "\n",
    "num_classes = 80\n",
    "batch_size = 2\n",
    "\n",
    "learning_rate_fn = tf.optimizers.schedules.PiecewiseConstantDecay(\n",
    "    boundaries=[125, 250, 500, 240000, 360000],\n",
    "\tvalues=[2.5e-06, 0.000625, 0.00125, 0.0025, 0.00025, 2.5e-05]\n",
    ")"
   ]
  },
  {
   "cell_type": "code",
   "execution_count": 8,
   "metadata": {},
   "outputs": [
    {
     "name": "stdout",
     "output_type": "stream",
     "text": [
      "Downloading data from https://storage.googleapis.com/tensorflow/keras-applications/resnet/resnet50_weights_tf_dim_ordering_tf_kernels_notop.h5\n",
      "94765736/94765736 [==============================] - 16s 0us/step\n"
     ]
    },
    {
     "name": "stderr",
     "output_type": "stream",
     "text": [
      "/home/mihawb/.local/lib/python3.11/site-packages/keras/src/initializers/initializers.py:120: UserWarning: The initializer RandomNormal is unseeded and being called multiple times, which will return identical values each time (even if the initializer is unseeded). Please update your code to provide a seed to the initializer, or avoid using the same initializer instance more than once.\n",
      "  warnings.warn(\n"
     ]
    }
   ],
   "source": [
    "resnet50_backbone = get_backbone()\n",
    "loss_fn = RetinaNetLoss(num_classes)\n",
    "model = RetinaNet(num_classes, resnet50_backbone)\n",
    "\n",
    "optimizer = tf.keras.optimizers.legacy.SGD(learning_rate=learning_rate_fn, momentum=0.9)\n",
    "model.compile(loss=loss_fn, optimizer=optimizer)\n"
   ]
  },
  {
   "cell_type": "code",
   "execution_count": 9,
   "metadata": {},
   "outputs": [
    {
     "name": "stderr",
     "output_type": "stream",
     "text": [
      "WARNING:absl:You use TensorFlow DType <dtype: 'int64'> in tfds.features This will soon be deprecated in favor of NumPy DTypes. In the meantime it was converted to int64.\n"
     ]
    }
   ],
   "source": [
    "(train_dataset, val_dataset), dataset_info = tfds.load(\n",
    "    \"coco/2017\", split=[\"train\", \"validation\"], with_info=True, data_dir=\"../../datasets/coco2017_test_trunc\"\n",
    ")"
   ]
  },
  {
   "cell_type": "code",
   "execution_count": 12,
   "metadata": {},
   "outputs": [
    {
     "name": "stdout",
     "output_type": "stream",
     "text": [
      "WARNING:tensorflow:From /tmp/ipykernel_4132/727034297.py:10: ignore_errors (from tensorflow.python.data.experimental.ops.error_ops) is deprecated and will be removed in a future version.\n",
      "Instructions for updating:\n",
      "Use `tf.data.Dataset.ignore_errors` instead.\n"
     ]
    },
    {
     "name": "stderr",
     "output_type": "stream",
     "text": [
      "WARNING:tensorflow:From /tmp/ipykernel_4132/727034297.py:10: ignore_errors (from tensorflow.python.data.experimental.ops.error_ops) is deprecated and will be removed in a future version.\n",
      "Instructions for updating:\n",
      "Use `tf.data.Dataset.ignore_errors` instead.\n"
     ]
    }
   ],
   "source": [
    "autotune = tf.data.AUTOTUNE\n",
    "train_dataset = train_dataset.map(preprocess_data, num_parallel_calls=autotune)\n",
    "train_dataset = train_dataset.shuffle(8 * batch_size)\n",
    "train_dataset = train_dataset.padded_batch(\n",
    "    batch_size=batch_size, padding_values=(0.0, 1e-8, -1), drop_remainder=True\n",
    ")\n",
    "train_dataset = train_dataset.map(\n",
    "    label_encoder.encode_batch, num_parallel_calls=autotune\n",
    ")\n",
    "train_dataset = train_dataset.apply(tf.data.experimental.ignore_errors())\n",
    "train_dataset = train_dataset.prefetch(autotune)\n",
    "\n",
    "val_dataset = val_dataset.map(preprocess_data, num_parallel_calls=autotune)\n",
    "val_dataset = val_dataset.padded_batch(\n",
    "    batch_size=1, padding_values=(0.0, 1e-8, -1), drop_remainder=True\n",
    ")\n",
    "val_dataset = val_dataset.map(label_encoder.encode_batch, num_parallel_calls=autotune)\n",
    "val_dataset = val_dataset.apply(tf.data.experimental.ignore_errors())\n",
    "val_dataset = val_dataset.prefetch(autotune)\n"
   ]
  },
  {
   "cell_type": "code",
   "execution_count": 13,
   "metadata": {},
   "outputs": [
    {
     "name": "stderr",
     "output_type": "stream",
     "text": [
      "2023-12-10 14:50:09.496527: I tensorflow/compiler/xla/stream_executor/cuda/cuda_dnn.cc:432] Loaded cuDNN version 8600\n",
      "2023-12-10 14:50:16.767069: W tensorflow/tsl/framework/bfc_allocator.cc:296] Allocator (GPU_0_bfc) ran out of memory trying to allocate 420.25MiB with freed_by_count=0. The caller indicates that this is not a failure, but this may mean that there could be performance gains if more memory were available.\n",
      "2023-12-10 14:50:16.791329: W tensorflow/tsl/framework/bfc_allocator.cc:296] Allocator (GPU_0_bfc) ran out of memory trying to allocate 420.25MiB with freed_by_count=0. The caller indicates that this is not a failure, but this may mean that there could be performance gains if more memory were available.\n",
      "2023-12-10 14:50:16.807688: E tensorflow/compiler/xla/stream_executor/cuda/cuda_blas.cc:190] failed to create cublas handle: the resource allocation failed\n",
      "2023-12-10 14:50:16.807778: E tensorflow/compiler/xla/stream_executor/cuda/cuda_blas.cc:193] Failure to initialize cublas may be due to OOM (cublas needs some free memory when you initialize it, and your deep-learning framework may have preallocated more than its fair share), or may be because this binary was not built with support for the GPU in your machine.\n",
      "2023-12-10 14:50:16.817813: W tensorflow/core/kernels/conv_ops_gpu.cc:321] None of the algorithms provided by cuDNN frontend heuristics worked; trying fallback algorithms.  Conv: batch: 2\n",
      "in_depths: 3\n",
      "out_depths: 64\n",
      "in: 1030\n",
      "in: 1414\n",
      "data_format: 1\n",
      "filter: 7\n",
      "filter: 7\n",
      "filter: 3\n",
      "dilation: 1\n",
      "dilation: 1\n",
      "stride: 2\n",
      "stride: 2\n",
      "padding: 0\n",
      "padding: 0\n",
      "dtype: DT_FLOAT\n",
      "group_count: 1\n",
      "device_identifier: \"sm_6.1 with 2094333952B RAM, 5 cores, 1455000KHz clock, 3504000KHz mem clock, 1048576B L2$\"\n",
      "version: 3\n",
      "\n",
      "2023-12-10 14:50:16.829245: E tensorflow/compiler/xla/stream_executor/cuda/cuda_blas.cc:190] failed to create cublas handle: the resource allocation failed\n",
      "2023-12-10 14:50:16.829298: E tensorflow/compiler/xla/stream_executor/cuda/cuda_blas.cc:193] Failure to initialize cublas may be due to OOM (cublas needs some free memory when you initialize it, and your deep-learning framework may have preallocated more than its fair share), or may be because this binary was not built with support for the GPU in your machine.\n",
      "2023-12-10 14:50:16.845959: W tensorflow/core/framework/op_kernel.cc:1828] OP_REQUIRES failed at conv_ops_impl.h:770 : NOT_FOUND: No algorithm worked!  Error messages:\n",
      "  Profiling failure on CUDNN engine eng1{}: UNKNOWN: CUDNN_STATUS_ALLOC_FAILED\n",
      "in tensorflow/compiler/xla/stream_executor/cuda/cuda_dnn.cc(5299): 'status'\n",
      "  Profiling failure on CUDNN engine eng28{}: UNKNOWN: CUDNN_STATUS_ALLOC_FAILED\n",
      "in tensorflow/compiler/xla/stream_executor/cuda/cuda_dnn.cc(5299): 'status'\n",
      "  Profiling failure on CUDNN engine eng0{}: UNKNOWN: CUDNN_STATUS_ALLOC_FAILED\n",
      "in tensorflow/compiler/xla/stream_executor/cuda/cuda_dnn.cc(5299): 'status'\n",
      "  Profiling failure on CUDNN engine eng4{}: UNKNOWN: CUDNN_STATUS_INTERNAL_ERROR\n",
      "in tensorflow/compiler/xla/stream_executor/cuda/cuda_dnn.cc(5299): 'status'\n"
     ]
    },
    {
     "ename": "NotFoundError",
     "evalue": "Graph execution error:\n\nDetected at node 'RetinaNet/FeaturePyramid/model/conv1_conv/Conv2D' defined at (most recent call last):\n    File \"<frozen runpy>\", line 198, in _run_module_as_main\n    File \"<frozen runpy>\", line 88, in _run_code\n    File \"/home/mihawb/.local/lib/python3.11/site-packages/ipykernel_launcher.py\", line 17, in <module>\n      app.launch_new_instance()\n    File \"/home/mihawb/.local/lib/python3.11/site-packages/traitlets/config/application.py\", line 1053, in launch_instance\n      app.start()\n    File \"/home/mihawb/.local/lib/python3.11/site-packages/ipykernel/kernelapp.py\", line 736, in start\n      self.io_loop.start()\n    File \"/home/mihawb/.local/lib/python3.11/site-packages/tornado/platform/asyncio.py\", line 195, in start\n      self.asyncio_loop.run_forever()\n    File \"/usr/lib/python3.11/asyncio/base_events.py\", line 607, in run_forever\n      self._run_once()\n    File \"/usr/lib/python3.11/asyncio/base_events.py\", line 1922, in _run_once\n      handle._run()\n    File \"/usr/lib/python3.11/asyncio/events.py\", line 80, in _run\n      self._context.run(self._callback, *self._args)\n    File \"/home/mihawb/.local/lib/python3.11/site-packages/ipykernel/kernelbase.py\", line 516, in dispatch_queue\n      await self.process_one()\n    File \"/home/mihawb/.local/lib/python3.11/site-packages/ipykernel/kernelbase.py\", line 505, in process_one\n      await dispatch(*args)\n    File \"/home/mihawb/.local/lib/python3.11/site-packages/ipykernel/kernelbase.py\", line 412, in dispatch_shell\n      await result\n    File \"/home/mihawb/.local/lib/python3.11/site-packages/ipykernel/kernelbase.py\", line 740, in execute_request\n      reply_content = await reply_content\n    File \"/home/mihawb/.local/lib/python3.11/site-packages/ipykernel/ipkernel.py\", line 422, in do_execute\n      res = shell.run_cell(\n    File \"/home/mihawb/.local/lib/python3.11/site-packages/ipykernel/zmqshell.py\", line 546, in run_cell\n      return super().run_cell(*args, **kwargs)\n    File \"/home/mihawb/.local/lib/python3.11/site-packages/IPython/core/interactiveshell.py\", line 3024, in run_cell\n      result = self._run_cell(\n    File \"/home/mihawb/.local/lib/python3.11/site-packages/IPython/core/interactiveshell.py\", line 3079, in _run_cell\n      result = runner(coro)\n    File \"/home/mihawb/.local/lib/python3.11/site-packages/IPython/core/async_helpers.py\", line 129, in _pseudo_sync_runner\n      coro.send(None)\n    File \"/home/mihawb/.local/lib/python3.11/site-packages/IPython/core/interactiveshell.py\", line 3284, in run_cell_async\n      has_raised = await self.run_ast_nodes(code_ast.body, cell_name,\n    File \"/home/mihawb/.local/lib/python3.11/site-packages/IPython/core/interactiveshell.py\", line 3466, in run_ast_nodes\n      if await self.run_code(code, result, async_=asy):\n    File \"/home/mihawb/.local/lib/python3.11/site-packages/IPython/core/interactiveshell.py\", line 3526, in run_code\n      exec(code_obj, self.user_global_ns, self.user_ns)\n    File \"/tmp/ipykernel_4132/1153254225.py\", line 14, in <module>\n      model.fit(\n    File \"/home/mihawb/.local/lib/python3.11/site-packages/keras/src/utils/traceback_utils.py\", line 65, in error_handler\n      return fn(*args, **kwargs)\n    File \"/home/mihawb/.local/lib/python3.11/site-packages/keras/src/engine/training.py\", line 1742, in fit\n      tmp_logs = self.train_function(iterator)\n    File \"/home/mihawb/.local/lib/python3.11/site-packages/keras/src/engine/training.py\", line 1338, in train_function\n      return step_function(self, iterator)\n    File \"/home/mihawb/.local/lib/python3.11/site-packages/keras/src/engine/training.py\", line 1322, in step_function\n      outputs = model.distribute_strategy.run(run_step, args=(data,))\n    File \"/home/mihawb/.local/lib/python3.11/site-packages/keras/src/engine/training.py\", line 1303, in run_step\n      outputs = model.train_step(data)\n    File \"/home/mihawb/.local/lib/python3.11/site-packages/keras/src/engine/training.py\", line 1080, in train_step\n      y_pred = self(x, training=True)\n    File \"/home/mihawb/.local/lib/python3.11/site-packages/keras/src/utils/traceback_utils.py\", line 65, in error_handler\n      return fn(*args, **kwargs)\n    File \"/home/mihawb/.local/lib/python3.11/site-packages/keras/src/engine/training.py\", line 569, in __call__\n      return super().__call__(*args, **kwargs)\n    File \"/home/mihawb/.local/lib/python3.11/site-packages/keras/src/utils/traceback_utils.py\", line 65, in error_handler\n      return fn(*args, **kwargs)\n    File \"/home/mihawb/.local/lib/python3.11/site-packages/keras/src/engine/base_layer.py\", line 1150, in __call__\n      outputs = call_fn(inputs, *args, **kwargs)\n    File \"/home/mihawb/.local/lib/python3.11/site-packages/keras/src/utils/traceback_utils.py\", line 96, in error_handler\n      return fn(*args, **kwargs)\n    File \"/home/mihawb/dnn-lang-comparison/python/tensorflow/retinanet_funcs.py\", line 513, in call\n      features = self.fpn(image, training=training)\n    File \"/home/mihawb/.local/lib/python3.11/site-packages/keras/src/utils/traceback_utils.py\", line 65, in error_handler\n      return fn(*args, **kwargs)\n    File \"/home/mihawb/.local/lib/python3.11/site-packages/keras/src/engine/base_layer.py\", line 1150, in __call__\n      outputs = call_fn(inputs, *args, **kwargs)\n    File \"/home/mihawb/.local/lib/python3.11/site-packages/keras/src/utils/traceback_utils.py\", line 96, in error_handler\n      return fn(*args, **kwargs)\n    File \"/home/mihawb/dnn-lang-comparison/python/tensorflow/retinanet_funcs.py\", line 449, in call\n      c3_output, c4_output, c5_output = self.backbone(images, training=training)\n    File \"/home/mihawb/.local/lib/python3.11/site-packages/keras/src/utils/traceback_utils.py\", line 65, in error_handler\n      return fn(*args, **kwargs)\n    File \"/home/mihawb/.local/lib/python3.11/site-packages/keras/src/engine/training.py\", line 569, in __call__\n      return super().__call__(*args, **kwargs)\n    File \"/home/mihawb/.local/lib/python3.11/site-packages/keras/src/utils/traceback_utils.py\", line 65, in error_handler\n      return fn(*args, **kwargs)\n    File \"/home/mihawb/.local/lib/python3.11/site-packages/keras/src/engine/base_layer.py\", line 1150, in __call__\n      outputs = call_fn(inputs, *args, **kwargs)\n    File \"/home/mihawb/.local/lib/python3.11/site-packages/keras/src/utils/traceback_utils.py\", line 96, in error_handler\n      return fn(*args, **kwargs)\n    File \"/home/mihawb/.local/lib/python3.11/site-packages/keras/src/engine/functional.py\", line 512, in call\n      return self._run_internal_graph(inputs, training=training, mask=mask)\n    File \"/home/mihawb/.local/lib/python3.11/site-packages/keras/src/engine/functional.py\", line 669, in _run_internal_graph\n      outputs = node.layer(*args, **kwargs)\n    File \"/home/mihawb/.local/lib/python3.11/site-packages/keras/src/utils/traceback_utils.py\", line 65, in error_handler\n      return fn(*args, **kwargs)\n    File \"/home/mihawb/.local/lib/python3.11/site-packages/keras/src/engine/base_layer.py\", line 1150, in __call__\n      outputs = call_fn(inputs, *args, **kwargs)\n    File \"/home/mihawb/.local/lib/python3.11/site-packages/keras/src/utils/traceback_utils.py\", line 96, in error_handler\n      return fn(*args, **kwargs)\n    File \"/home/mihawb/.local/lib/python3.11/site-packages/keras/src/layers/convolutional/base_conv.py\", line 290, in call\n      outputs = self.convolution_op(inputs, self.kernel)\n    File \"/home/mihawb/.local/lib/python3.11/site-packages/keras/src/layers/convolutional/base_conv.py\", line 262, in convolution_op\n      return tf.nn.convolution(\nNode: 'RetinaNet/FeaturePyramid/model/conv1_conv/Conv2D'\nNo algorithm worked!  Error messages:\n  Profiling failure on CUDNN engine eng1{}: UNKNOWN: CUDNN_STATUS_ALLOC_FAILED\nin tensorflow/compiler/xla/stream_executor/cuda/cuda_dnn.cc(5299): 'status'\n  Profiling failure on CUDNN engine eng28{}: UNKNOWN: CUDNN_STATUS_ALLOC_FAILED\nin tensorflow/compiler/xla/stream_executor/cuda/cuda_dnn.cc(5299): 'status'\n  Profiling failure on CUDNN engine eng0{}: UNKNOWN: CUDNN_STATUS_ALLOC_FAILED\nin tensorflow/compiler/xla/stream_executor/cuda/cuda_dnn.cc(5299): 'status'\n  Profiling failure on CUDNN engine eng4{}: UNKNOWN: CUDNN_STATUS_INTERNAL_ERROR\nin tensorflow/compiler/xla/stream_executor/cuda/cuda_dnn.cc(5299): 'status'\n\t [[{{node RetinaNet/FeaturePyramid/model/conv1_conv/Conv2D}}]] [Op:__inference_train_function_17548]",
     "output_type": "error",
     "traceback": [
      "\u001b[0;31m---------------------------------------------------------------------------\u001b[0m",
      "\u001b[0;31mNotFoundError\u001b[0m                             Traceback (most recent call last)",
      "\u001b[1;32m/home/mihawb/dnn-lang-comparison/python/tensorflow/retinanet_sandbox.ipynb Cell 6\u001b[0m line \u001b[0;36m1\n\u001b[1;32m      <a href='vscode-notebook-cell://ssh-remote%2Bubdesktop/home/mihawb/dnn-lang-comparison/python/tensorflow/retinanet_sandbox.ipynb#W5sdnNjb2RlLXJlbW90ZQ%3D%3D?line=8'>9</a>\u001b[0m epochs \u001b[39m=\u001b[39m \u001b[39m1\u001b[39m\n\u001b[1;32m     <a href='vscode-notebook-cell://ssh-remote%2Bubdesktop/home/mihawb/dnn-lang-comparison/python/tensorflow/retinanet_sandbox.ipynb#W5sdnNjb2RlLXJlbW90ZQ%3D%3D?line=10'>11</a>\u001b[0m \u001b[39m# Running 100 training and 50 validation steps,\u001b[39;00m\n\u001b[1;32m     <a href='vscode-notebook-cell://ssh-remote%2Bubdesktop/home/mihawb/dnn-lang-comparison/python/tensorflow/retinanet_sandbox.ipynb#W5sdnNjb2RlLXJlbW90ZQ%3D%3D?line=11'>12</a>\u001b[0m \u001b[39m# remove `.take` when training on the full dataset\u001b[39;00m\n\u001b[0;32m---> <a href='vscode-notebook-cell://ssh-remote%2Bubdesktop/home/mihawb/dnn-lang-comparison/python/tensorflow/retinanet_sandbox.ipynb#W5sdnNjb2RlLXJlbW90ZQ%3D%3D?line=13'>14</a>\u001b[0m model\u001b[39m.\u001b[39;49mfit(\n\u001b[1;32m     <a href='vscode-notebook-cell://ssh-remote%2Bubdesktop/home/mihawb/dnn-lang-comparison/python/tensorflow/retinanet_sandbox.ipynb#W5sdnNjb2RlLXJlbW90ZQ%3D%3D?line=14'>15</a>\u001b[0m     train_dataset\u001b[39m.\u001b[39;49mtake(\u001b[39m100\u001b[39;49m),\n\u001b[1;32m     <a href='vscode-notebook-cell://ssh-remote%2Bubdesktop/home/mihawb/dnn-lang-comparison/python/tensorflow/retinanet_sandbox.ipynb#W5sdnNjb2RlLXJlbW90ZQ%3D%3D?line=15'>16</a>\u001b[0m     validation_data\u001b[39m=\u001b[39;49mval_dataset\u001b[39m.\u001b[39;49mtake(\u001b[39m50\u001b[39;49m),\n\u001b[1;32m     <a href='vscode-notebook-cell://ssh-remote%2Bubdesktop/home/mihawb/dnn-lang-comparison/python/tensorflow/retinanet_sandbox.ipynb#W5sdnNjb2RlLXJlbW90ZQ%3D%3D?line=16'>17</a>\u001b[0m     epochs\u001b[39m=\u001b[39;49mepochs,\n\u001b[1;32m     <a href='vscode-notebook-cell://ssh-remote%2Bubdesktop/home/mihawb/dnn-lang-comparison/python/tensorflow/retinanet_sandbox.ipynb#W5sdnNjb2RlLXJlbW90ZQ%3D%3D?line=17'>18</a>\u001b[0m     verbose\u001b[39m=\u001b[39;49m\u001b[39m1\u001b[39;49m,\n\u001b[1;32m     <a href='vscode-notebook-cell://ssh-remote%2Bubdesktop/home/mihawb/dnn-lang-comparison/python/tensorflow/retinanet_sandbox.ipynb#W5sdnNjb2RlLXJlbW90ZQ%3D%3D?line=18'>19</a>\u001b[0m )\n",
      "File \u001b[0;32m~/.local/lib/python3.11/site-packages/keras/src/utils/traceback_utils.py:70\u001b[0m, in \u001b[0;36mfilter_traceback.<locals>.error_handler\u001b[0;34m(*args, **kwargs)\u001b[0m\n\u001b[1;32m     67\u001b[0m     filtered_tb \u001b[39m=\u001b[39m _process_traceback_frames(e\u001b[39m.\u001b[39m__traceback__)\n\u001b[1;32m     68\u001b[0m     \u001b[39m# To get the full stack trace, call:\u001b[39;00m\n\u001b[1;32m     69\u001b[0m     \u001b[39m# `tf.debugging.disable_traceback_filtering()`\u001b[39;00m\n\u001b[0;32m---> 70\u001b[0m     \u001b[39mraise\u001b[39;00m e\u001b[39m.\u001b[39mwith_traceback(filtered_tb) \u001b[39mfrom\u001b[39;00m \u001b[39mNone\u001b[39;00m\n\u001b[1;32m     71\u001b[0m \u001b[39mfinally\u001b[39;00m:\n\u001b[1;32m     72\u001b[0m     \u001b[39mdel\u001b[39;00m filtered_tb\n",
      "File \u001b[0;32m~/.local/lib/python3.11/site-packages/tensorflow/python/eager/execute.py:53\u001b[0m, in \u001b[0;36mquick_execute\u001b[0;34m(op_name, num_outputs, inputs, attrs, ctx, name)\u001b[0m\n\u001b[1;32m     51\u001b[0m \u001b[39mtry\u001b[39;00m:\n\u001b[1;32m     52\u001b[0m   ctx\u001b[39m.\u001b[39mensure_initialized()\n\u001b[0;32m---> 53\u001b[0m   tensors \u001b[39m=\u001b[39m pywrap_tfe\u001b[39m.\u001b[39mTFE_Py_Execute(ctx\u001b[39m.\u001b[39m_handle, device_name, op_name,\n\u001b[1;32m     54\u001b[0m                                       inputs, attrs, num_outputs)\n\u001b[1;32m     55\u001b[0m \u001b[39mexcept\u001b[39;00m core\u001b[39m.\u001b[39m_NotOkStatusException \u001b[39mas\u001b[39;00m e:\n\u001b[1;32m     56\u001b[0m   \u001b[39mif\u001b[39;00m name \u001b[39mis\u001b[39;00m \u001b[39mnot\u001b[39;00m \u001b[39mNone\u001b[39;00m:\n",
      "\u001b[0;31mNotFoundError\u001b[0m: Graph execution error:\n\nDetected at node 'RetinaNet/FeaturePyramid/model/conv1_conv/Conv2D' defined at (most recent call last):\n    File \"<frozen runpy>\", line 198, in _run_module_as_main\n    File \"<frozen runpy>\", line 88, in _run_code\n    File \"/home/mihawb/.local/lib/python3.11/site-packages/ipykernel_launcher.py\", line 17, in <module>\n      app.launch_new_instance()\n    File \"/home/mihawb/.local/lib/python3.11/site-packages/traitlets/config/application.py\", line 1053, in launch_instance\n      app.start()\n    File \"/home/mihawb/.local/lib/python3.11/site-packages/ipykernel/kernelapp.py\", line 736, in start\n      self.io_loop.start()\n    File \"/home/mihawb/.local/lib/python3.11/site-packages/tornado/platform/asyncio.py\", line 195, in start\n      self.asyncio_loop.run_forever()\n    File \"/usr/lib/python3.11/asyncio/base_events.py\", line 607, in run_forever\n      self._run_once()\n    File \"/usr/lib/python3.11/asyncio/base_events.py\", line 1922, in _run_once\n      handle._run()\n    File \"/usr/lib/python3.11/asyncio/events.py\", line 80, in _run\n      self._context.run(self._callback, *self._args)\n    File \"/home/mihawb/.local/lib/python3.11/site-packages/ipykernel/kernelbase.py\", line 516, in dispatch_queue\n      await self.process_one()\n    File \"/home/mihawb/.local/lib/python3.11/site-packages/ipykernel/kernelbase.py\", line 505, in process_one\n      await dispatch(*args)\n    File \"/home/mihawb/.local/lib/python3.11/site-packages/ipykernel/kernelbase.py\", line 412, in dispatch_shell\n      await result\n    File \"/home/mihawb/.local/lib/python3.11/site-packages/ipykernel/kernelbase.py\", line 740, in execute_request\n      reply_content = await reply_content\n    File \"/home/mihawb/.local/lib/python3.11/site-packages/ipykernel/ipkernel.py\", line 422, in do_execute\n      res = shell.run_cell(\n    File \"/home/mihawb/.local/lib/python3.11/site-packages/ipykernel/zmqshell.py\", line 546, in run_cell\n      return super().run_cell(*args, **kwargs)\n    File \"/home/mihawb/.local/lib/python3.11/site-packages/IPython/core/interactiveshell.py\", line 3024, in run_cell\n      result = self._run_cell(\n    File \"/home/mihawb/.local/lib/python3.11/site-packages/IPython/core/interactiveshell.py\", line 3079, in _run_cell\n      result = runner(coro)\n    File \"/home/mihawb/.local/lib/python3.11/site-packages/IPython/core/async_helpers.py\", line 129, in _pseudo_sync_runner\n      coro.send(None)\n    File \"/home/mihawb/.local/lib/python3.11/site-packages/IPython/core/interactiveshell.py\", line 3284, in run_cell_async\n      has_raised = await self.run_ast_nodes(code_ast.body, cell_name,\n    File \"/home/mihawb/.local/lib/python3.11/site-packages/IPython/core/interactiveshell.py\", line 3466, in run_ast_nodes\n      if await self.run_code(code, result, async_=asy):\n    File \"/home/mihawb/.local/lib/python3.11/site-packages/IPython/core/interactiveshell.py\", line 3526, in run_code\n      exec(code_obj, self.user_global_ns, self.user_ns)\n    File \"/tmp/ipykernel_4132/1153254225.py\", line 14, in <module>\n      model.fit(\n    File \"/home/mihawb/.local/lib/python3.11/site-packages/keras/src/utils/traceback_utils.py\", line 65, in error_handler\n      return fn(*args, **kwargs)\n    File \"/home/mihawb/.local/lib/python3.11/site-packages/keras/src/engine/training.py\", line 1742, in fit\n      tmp_logs = self.train_function(iterator)\n    File \"/home/mihawb/.local/lib/python3.11/site-packages/keras/src/engine/training.py\", line 1338, in train_function\n      return step_function(self, iterator)\n    File \"/home/mihawb/.local/lib/python3.11/site-packages/keras/src/engine/training.py\", line 1322, in step_function\n      outputs = model.distribute_strategy.run(run_step, args=(data,))\n    File \"/home/mihawb/.local/lib/python3.11/site-packages/keras/src/engine/training.py\", line 1303, in run_step\n      outputs = model.train_step(data)\n    File \"/home/mihawb/.local/lib/python3.11/site-packages/keras/src/engine/training.py\", line 1080, in train_step\n      y_pred = self(x, training=True)\n    File \"/home/mihawb/.local/lib/python3.11/site-packages/keras/src/utils/traceback_utils.py\", line 65, in error_handler\n      return fn(*args, **kwargs)\n    File \"/home/mihawb/.local/lib/python3.11/site-packages/keras/src/engine/training.py\", line 569, in __call__\n      return super().__call__(*args, **kwargs)\n    File \"/home/mihawb/.local/lib/python3.11/site-packages/keras/src/utils/traceback_utils.py\", line 65, in error_handler\n      return fn(*args, **kwargs)\n    File \"/home/mihawb/.local/lib/python3.11/site-packages/keras/src/engine/base_layer.py\", line 1150, in __call__\n      outputs = call_fn(inputs, *args, **kwargs)\n    File \"/home/mihawb/.local/lib/python3.11/site-packages/keras/src/utils/traceback_utils.py\", line 96, in error_handler\n      return fn(*args, **kwargs)\n    File \"/home/mihawb/dnn-lang-comparison/python/tensorflow/retinanet_funcs.py\", line 513, in call\n      features = self.fpn(image, training=training)\n    File \"/home/mihawb/.local/lib/python3.11/site-packages/keras/src/utils/traceback_utils.py\", line 65, in error_handler\n      return fn(*args, **kwargs)\n    File \"/home/mihawb/.local/lib/python3.11/site-packages/keras/src/engine/base_layer.py\", line 1150, in __call__\n      outputs = call_fn(inputs, *args, **kwargs)\n    File \"/home/mihawb/.local/lib/python3.11/site-packages/keras/src/utils/traceback_utils.py\", line 96, in error_handler\n      return fn(*args, **kwargs)\n    File \"/home/mihawb/dnn-lang-comparison/python/tensorflow/retinanet_funcs.py\", line 449, in call\n      c3_output, c4_output, c5_output = self.backbone(images, training=training)\n    File \"/home/mihawb/.local/lib/python3.11/site-packages/keras/src/utils/traceback_utils.py\", line 65, in error_handler\n      return fn(*args, **kwargs)\n    File \"/home/mihawb/.local/lib/python3.11/site-packages/keras/src/engine/training.py\", line 569, in __call__\n      return super().__call__(*args, **kwargs)\n    File \"/home/mihawb/.local/lib/python3.11/site-packages/keras/src/utils/traceback_utils.py\", line 65, in error_handler\n      return fn(*args, **kwargs)\n    File \"/home/mihawb/.local/lib/python3.11/site-packages/keras/src/engine/base_layer.py\", line 1150, in __call__\n      outputs = call_fn(inputs, *args, **kwargs)\n    File \"/home/mihawb/.local/lib/python3.11/site-packages/keras/src/utils/traceback_utils.py\", line 96, in error_handler\n      return fn(*args, **kwargs)\n    File \"/home/mihawb/.local/lib/python3.11/site-packages/keras/src/engine/functional.py\", line 512, in call\n      return self._run_internal_graph(inputs, training=training, mask=mask)\n    File \"/home/mihawb/.local/lib/python3.11/site-packages/keras/src/engine/functional.py\", line 669, in _run_internal_graph\n      outputs = node.layer(*args, **kwargs)\n    File \"/home/mihawb/.local/lib/python3.11/site-packages/keras/src/utils/traceback_utils.py\", line 65, in error_handler\n      return fn(*args, **kwargs)\n    File \"/home/mihawb/.local/lib/python3.11/site-packages/keras/src/engine/base_layer.py\", line 1150, in __call__\n      outputs = call_fn(inputs, *args, **kwargs)\n    File \"/home/mihawb/.local/lib/python3.11/site-packages/keras/src/utils/traceback_utils.py\", line 96, in error_handler\n      return fn(*args, **kwargs)\n    File \"/home/mihawb/.local/lib/python3.11/site-packages/keras/src/layers/convolutional/base_conv.py\", line 290, in call\n      outputs = self.convolution_op(inputs, self.kernel)\n    File \"/home/mihawb/.local/lib/python3.11/site-packages/keras/src/layers/convolutional/base_conv.py\", line 262, in convolution_op\n      return tf.nn.convolution(\nNode: 'RetinaNet/FeaturePyramid/model/conv1_conv/Conv2D'\nNo algorithm worked!  Error messages:\n  Profiling failure on CUDNN engine eng1{}: UNKNOWN: CUDNN_STATUS_ALLOC_FAILED\nin tensorflow/compiler/xla/stream_executor/cuda/cuda_dnn.cc(5299): 'status'\n  Profiling failure on CUDNN engine eng28{}: UNKNOWN: CUDNN_STATUS_ALLOC_FAILED\nin tensorflow/compiler/xla/stream_executor/cuda/cuda_dnn.cc(5299): 'status'\n  Profiling failure on CUDNN engine eng0{}: UNKNOWN: CUDNN_STATUS_ALLOC_FAILED\nin tensorflow/compiler/xla/stream_executor/cuda/cuda_dnn.cc(5299): 'status'\n  Profiling failure on CUDNN engine eng4{}: UNKNOWN: CUDNN_STATUS_INTERNAL_ERROR\nin tensorflow/compiler/xla/stream_executor/cuda/cuda_dnn.cc(5299): 'status'\n\t [[{{node RetinaNet/FeaturePyramid/model/conv1_conv/Conv2D}}]] [Op:__inference_train_function_17548]"
     ]
    }
   ],
   "source": [
    "# Uncomment the following lines, when training on full dataset\n",
    "# train_steps_per_epoch = dataset_info.splits[\"train\"].num_examples // batch_size\n",
    "# val_steps_per_epoch = \\\n",
    "#     dataset_info.splits[\"validation\"].num_examples // batch_size\n",
    "\n",
    "# train_steps = 4 * 100000\n",
    "# epochs = train_steps // train_steps_per_epoch\n",
    "\n",
    "epochs = 1\n",
    "\n",
    "# Running 100 training and 50 validation steps,\n",
    "# remove `.take` when training on the full dataset\n",
    "\n",
    "model.fit(\n",
    "    train_dataset.take(100),\n",
    "    validation_data=val_dataset.take(50),\n",
    "    epochs=epochs,\n",
    "    verbose=1,\n",
    ")\n"
   ]
  }
 ],
 "metadata": {
  "kernelspec": {
   "display_name": "Python 3",
   "language": "python",
   "name": "python3"
  },
  "language_info": {
   "codemirror_mode": {
    "name": "ipython",
    "version": 3
   },
   "file_extension": ".py",
   "mimetype": "text/x-python",
   "name": "python",
   "nbconvert_exporter": "python",
   "pygments_lexer": "ipython3",
   "version": "3.11.5"
  }
 },
 "nbformat": 4,
 "nbformat_minor": 2
}
